---
title: async函数处理异常的方式
author: hanxitao
date: 2022-04-21 19:46:00 +0800
categories: [javascript]
tags: [js相关]
---

## 一、返回Promise对象

async函数返回一个Promise对象。

async函数内部return语句返回的值会成为then方法回调函数的参数。

```javascript
async function f() {
    return 'hello world';
}

f().then(v => console.log(v)); // hello world
```

async函数内部抛出错误，会导致返回的Promise变为rejected状态。抛出的错误对象会被catch方法的回调函数接收到。

await命令后面的Promise对象如果变为rejected状态，则reject的参数会被catch方法的回调函数接收到。

```javascript
async function f() {
    // throw new Error('出错了');
    await Promise.reject('出错了');
}

f().then(
    v => console.log(v),
    e => console.log(e)
); // Error：出错了
```

async函数返回的Promise对象必须等到所有await命令后面的Promise对象执行完，才会发生状态改变，除非遇到return语句或者抛出错误。

## 二、async函数中的错误处理

任何一个await语句后面的Promise对象变为rejected状态，那么整个async函数都会中断执行。

1. 处理方式一：try...catch

```javascript
const fetchData = () => {
    return new Promise((resolve, reject) => {
        setTimeout(() => {
            reject('出错了');
        }, 1000);
    });
}

(async () => {
    try {
        const data = await fetchData();
    } catch(err) {
        console.log(err); // Error: 出错了
    }
})();
```

2. 方式二：Result Pattern模式

```javascript
(async () => {
    const [data, err] = await fetchData()
        .then(data => [data, null])
        .catch(err => [null, err]);
    
    console.log('err：', err);
    console.log('data：', data);
})();
```